package Oops;

public class finallyBlock {
    public static void main(String[] args) {
        // if exception occur
        // try {
        // int a=100,b=0,c;
        // c= a/b;
        // System.out.println(c);
        // } catch (Throwable e) {
        // System.out.println(e);
        // }
        // finally{
        // System.out.println("12345");
        // }

        // if exception does not occur
        // try {
        //     int a = 100, b = 2, c;
        //     c = a / b;
        //     System.out.println(c);
        // } catch (Throwable e) {
        //     System.out.println(e);
        // } finally {
        //     System.out.println("12345");

        // it can use after also but it will resolve or handle exception
        // try {
        //     int a = 100, b = 0, c;
        //     c = a / b;
        //     System.out.println(c);
        // } finally {
        //     System.out.println("12345");
        // }

        //  we can use try catch inside in finnally block
        }
    }


